Workbook

Sheet Hoja1
A1: ano_eje | B1: exp_siaf | C1: ESTADO | D1: TIPO_BIEN | E1: NRO_CERTIFICA_SIAF | F1: NRO_ORDEN | G1: CENTRO_COSTO | H1: NOMBRE_DEPEND | I1: CODIGO_TAREA | J1: nombre_tarea | K1: GRUPO_BIEN | L1: CLASE_BIEN | M1: FAMILIA_BIEN | N1: ITEM_BIEN | O1: NOMBRE_ITEM | P1: NOMBRE | Q1: CANTIDAD_UNITARIO | R1: PRECIO_UNIT | S1: NRO_RUC | T1: NOMBRE_PROV | U1: fuente_financ | V1: nombre_ff | W1: clasificador | X1: NOMBRE_CLASIF | Y1: sec_func | Z1: prod_pry | AA1: monto_nacional | AB1: FECHA_DEVENGADO
A2: 2026 | B2: 1527 | C2: 2 | D2: B | E2: 1124 | F2: 231 | G2: 94.01 | H2: ORGANO DE CONTROL INSTITUCIONAL | I2: 90 | J2: REALIZACIÓN DE SERVICIOS DE CONTROL RELACIONADO | K2: 71 | L2: 72 | M2: 5 | N2: 224 | O2: PAPEL BOND 80 G TAMAÑO A4 | P2: EMPAQUE X 500 | Q2: 50 | R2: 12.98 | S2: 20609592789 | T2: STCASMAE.I.R.L. | U2: 00 | V2: =VLOOKUP(U2,d_ff!A$1:B$5,2,0) -> 00: RECURSOS ORDINARIOS | W2: 2.3. 1 5. 1 2 | X2: =VLOOKUP(W2,d_clasif!B$1:C$1529,2,0) -> 2.3. 1 5. 1 2: PAPELERIA EN GENERAL, UTILES Y MATERIALES DE OFICINA | Y2: 45 | Z2: Cadenas Presupuestal: Siaf/Ord: 1527/231 | AA2: 649 | AB2: 46185
A3: 2026 | B3: 1527 | C3: 2 | D3: B | E3: 1124 | F3: 231 | G3: 94.01 | H3: ORGANO DE CONTROL INSTITUCIONAL | I3: 91 | J3: REALIZACIÓN DE SERVICIO DE CONTROL SIMULTANEO | K3: 71 | L3: 72 | M3: 5 | N3: 224 | O3: PAPEL BOND 80 G TAMAÑO A4 | P3: EMPAQUE X 500 | Q3: 50 | R3: 12.98 | S3: 20609592789 | T3: STCASMAE.I.R.L. | U3: 00 | V3: =VLOOKUP(U3,d_ff!A$1:B$5,2,0) -> 00: RECURSOS ORDINARIOS | W3: 2.3. 1 5. 1 2 | X3: =VLOOKUP(W3,d_clasif!B$1:C$1529,2,0) -> 2.3. 1 5. 1 2: PAPELERIA EN GENERAL, UTILES Y MATERIALES DE OFICINA | Y3: 45 | Z3: Cadenas Presupuestal: Siaf/Ord: 1527/231 | AA3: 649 | AB3: 46185
A4: 2026 | B4: 818 | C4: 2 | D4: B | E4: 586 | F4: 106 | G4: 94.02.02 | H4: OFICINA DE ASESORIA JURIDICA | I4: 14 | J4: ATENCIÓN DE ACCIONES DE ASESORAMIENTO JURÍDICO | K4: 71 | L4: 85 | M4: 8 | N4: 26 | O4: GRAPA 26/6 X 5000 | P4: UNIDAD | Q4: 100 | R4: 3.54 | S4: 20600944348 | T4: DISTRIBUIDORA UNIVERSAL ICA E.I.R.L | U4: 00 | V4: =VLOOKUP(U4,d_ff!A$1:B$5,2,0) -> 00: RECURSOS ORDINARIOS | W4: 2.3. 1 5. 1 2 | X4: =VLOOKUP(W4,d_clasif!B$1:C$1529,2,0) -> 2.3. 1 5. 1 2: PAPELERIA EN GENERAL, UTILES Y MATERIALES DE OFICINA | Y4: 43 | Z4: Cadenas Presupuestal: Siaf/Ord: 818/106 | AA4: 354 | AB4: 46164
A5: 2026 | B5: 1527 | C5: 2 | D5: B | E5: 1124 | F5: 231 | G5: 94.02.02 | H5: OFICINA DE ASESORIA JURIDICA | I5: 14 | J5: ATENCIÓN DE ACCIONES DE ASESORAMIENTO JURÍDICO | K5: 71 | L5: 72 | M5: 5 | N5: 224 | O5: PAPEL BOND 80 G TAMAÑO A4 | P5: EMPAQUE X 500 | Q5: 140 | R5: 12.98 | S5: 20609592789 | T5: STCASMAE.I.R.L. | U5: 00 | V5: =VLOOKUP(U5,d_ff!A$1:B$5,2,0) -> 00: RECURSOS ORDINARIOS | W5: 2.3. 1 5. 1 2 | X5: =VLOOKUP(W5,d_clasif!B$1:C$1529,2,0) -> 2.3. 1 5. 1 2: PAPELERIA EN GENERAL, UTILES Y MATERIALES DE OFICINA | Y5: 43 | Z5: Cadenas Presupuestal: Siaf/Ord: 1527/231 | AA5: 1817.2 | AB5: 46185
A6: 2026 | B6: 1046 | C6: 2 | D6: B | E6: 771 | F6: 143 | G6: 94.02.02 | H6: OFICINA DE ASESORIA JURIDICA | I6: 14 | J6: ATENCIÓN DE ACCIONES DE ASESORAMIENTO JURÍDICO | K6: 71 | L6: 85 | M6: 5 | N6: 58 | O6: CLIP DE METAL 30 mm APROX. X 100 | P6: UNIDAD | Q6: 30 | R6: 2.8 | S6: 10704570894 | T6: DIAZ CORDERO NICOLL FABIOLA | U6: 00 | V6: =VLOOKUP(U6,d_ff!A$1:B$5,2,0) -> 00: RECURSOS ORDINARIOS | W6: 2.3. 1 5. 1 2 | X6: =VLOOKUP(W6,d_clasif!B$1:C$1529,2,0) -> 2.3. 1 5. 1 2: PAPELERIA EN GENERAL, UTILES Y MATERIALES DE OFICINA | Y6: 43 | Z6: Cadenas Presupuestal: Siaf/Ord: 1046/143 | AA6: 84 | AB6: 46176
A7: 2026 | B7: 818 | C7: 2 | D7: B | E7: 586 | F7: 106 | G7: 94.02.02 | H7: OFICINA DE ASESORIA JURIDICA | I7: 14 | J7: ATENCIÓN DE ACCIONES DE ASESORAMIENTO JURÍDICO | K7: 50 | L7: 33 | M7: 25 | N7: 45 | O7: CINTA DE PLASTICO ADHESIVA PARA EMBALAJE 2 in X 110 yd | P7: UNIDAD | Q7: 50 | R7: 11.799971 | S7: 20600944348 | T7: DISTRIBUIDORA UNIVERSAL ICA E.I.R.L | U7: 00 | V7: =VLOOKUP(U7,d_ff!A$1:B$5,2,0) -> 00: RECURSOS ORDINARIOS | W7: 2.3. 1 5. 1 2 | X7: =VLOOKUP(W7,d_clasif!B$1:C$1529,2,0) -> 2.3. 1 5. 1 2: PAPELERIA EN GENERAL, UTILES Y MATERIALES DE OFICINA | Y7: 43 | Z7: Cadenas Presupuestal: Siaf/Ord: 818/106 | AA7: 590 | AB7: 46164
A8: 2026 | B8: 818 | C8: 2 | D8: B | E8: 586 | F8: 106 | G8: 94.02.02 | H8: OFICINA DE ASESORIA JURIDICA | I8: 14 | J8: ATENCIÓN DE ACCIONES DE ASESORAMIENTO JURÍDICO | K8: 71 | L8: 6 | M8: 4 | N8: 4 | O8: FOLDER MANILA TAMAÑO A4 | P8: UNIDAD | Q8: 600 | R8: 0.531 | S8: 20600944348 | T8: DISTRIBUIDORA UNIVERSAL ICA E.I.R.L | U8: 00 | V8: =VLOOKUP(U8,d_ff!A$1:B$5,2,0) -> 00: RECURSOS ORDINARIOS | W8: 2.3. 1 5. 1 2 | X8: =VLOOKUP(W8,d_clasif!B$1:C$1529,2,0) -> 2.3. 1 5. 1 2: PAPELERIA EN GENERAL, UTILES Y MATERIALES DE OFICINA | Y8: 43 | Z8: Cadenas Presupuestal: Siaf/Ord: 818/106 | AA8: 318.6 | AB8: 46164
A9: 2026 | B9: 818 | C9: 2 | D9: B | E9: 586 | F9: 106 | G9: 94.02.02 | H9: OFICINA DE ASESORIA JURIDICA | I9: 14 | J9: ATENCIÓN DE ACCIONES DE ASESORAMIENTO JURÍDICO | K9: 71 | L9: 6 | M9: 5 | N9: 13 | O9: FOLDER DE PLASTICO TAMAÑO A4 CON TAPA TRANSPARENTE | P9: UNIDAD | Q9: 25 | R9: 1.59303 | S9: 20600944348 | T9: DISTRIBUIDORA UNIVERSAL ICA E.I.R.L | U9: 00 | V9: =VLOOKUP(U9,d_ff!A$1:B$5,2,0) -> 00: RECURSOS ORDINARIOS | W9: 2.3. 1 5. 1 2 | X9: =VLOOKUP(W9,d_clasif!B$1:C$1529,2,0) -> 2.3. 1 5. 1 2: PAPELERIA EN GENERAL, UTILES Y MATERIALES DE OFICINA | Y9: 43 | Z9: Cadenas Presupuestal: Siaf/Ord: 818/106 | AA9: 39.83 | AB9: 46164
A10: 2026 | B10: 818 | C10: 2 | D10: B | E10: 586 | F10: 106 | G10: 94.02.02 | H10: OFICINA DE ASESORIA JURIDICA | I10: 14 | J10: ATENCIÓN DE ACCIONES DE ASESORAMIENTO JURÍDICO | K10: 71 | L10: 6 | M10: 6 | N10: 44 | O10: FORRO DE PLASTICO TRANSPARENTE TAMAÑO OFICIO X 5 m | P10: UNIDAD | Q10: 25 | R10: 8.118395 | S10: 20600944348 | T10: DISTRIBUIDORA UNIVERSAL ICA E.I.R.L | U10: 00 | V10: =VLOOKUP(U10,d_ff!A$1:B$5,2,0) -> 00: RECURSOS ORDINARIOS | W10: 2.3. 1 5. 1 2 | X10: =VLOOKUP(W10,d_clasif!B$1:C$1529,2,0) -> 2.3. 1 5. 1 2: PAPELERIA EN GENERAL, UTILES Y MATERIALES DE OFICINA | Y10: 43 | Z10: Cadenas Presupuestal: Siaf/Ord: 818/106 | AA10: 202.96 | AB10: 46164
A11: 2026 | B11: 818 | C11: 2 | D11: B | E11: 586 | F11: 106 | G11: 94.02.02 | H11: OFICINA DE ASESORIA JURIDICA | I11: 14 | J11: ATENCIÓN DE ACCIONES DE ASESORAMIENTO JURÍDICO | K11: 71 | L11: 72 | M11: 3 | N11: 227 | O11: CUADERNO DOBLE ESPIRAL CUADRICULADO TAMAÑO A4 X 200 HOJAS | P11: UNIDAD | Q11: 17 | R11: 34.81 | S11: 20600944348 | T11: DISTRIBUIDORA UNIVERSAL ICA E.I.R.L | U11: 00 | V11: =VLOOKUP(U11,d_ff!A$1:B$5,2,0) -> 00: RECURSOS ORDINARIOS | W11: 2.3. 1 5. 1 2 | X11: =VLOOKUP(W11,d_clasif!B$1:C$1529,2,0) -> 2.3. 1 5. 1 2: PAPELERIA EN GENERAL, UTILES Y MATERIALES DE OFICINA | Y11: 43 | Z11: Cadenas Presupuestal: Siaf/Ord: 818/106 | AA11: 591.77 | AB11: 46164
A12: 2026 | B12: 1046 | C12: 2 | D12: B | E12: 771 | F12: 143 | G12: 94.02.02 | H12: OFICINA DE ASESORIA JURIDICA | I12: 14 | J12: ATENCIÓN DE ACCIONES DE ASESORAMIENTO JURÍDICO | K12: 71 | L12: 85 | M12: 5 | N12: 46 | O12: CLIP DE METAL 50 mm X 100 | P12: UNIDAD | Q12: 24 | R12: 5 | S12: 10704570894 | T12: DIAZ CORDERO NICOLL FABIOLA | U12: 00 | V12: =VLOOKUP(U12,d_ff!A$1:B$5,2,0) -> 00: RECURSOS ORDINARIOS | W12: 2.3. 1 5. 1 2 | X12: =VLOOKUP(W12,d_clasif!B$1:C$1529,2,0) -> 2.3. 1 5. 1 2: PAPELERIA EN GENERAL, UTILES Y MATERIALES DE OFICINA | Y12: 43 | Z12: Cadenas Presupuestal: Siaf/Ord: 1046/143 | AA12: 120 | AB12: 46176
A13: 2026 | B13: 818 | C13: 2 | D13: B | E13: 586 | F13: 106 | G13: 94.02.02 | H13: OFICINA DE ASESORIA JURIDICA | I13: 252 | J13: ATENCIÓN DE ACCIONES DE DEFENSA LEGAL DE LOS INTERESES INSTITUCIONALES EN PROCESOS JUDICIALES | K13: 71 | L13: 50 | M13: 11 | N13: 88 | O13: ENGRAPADOR TIPO ALICATE PARA 50 HOJAS APROX. | P13: UNIDAD | Q13: 9 | R13: 44.25 | S13: 20600944348 | T13: DISTRIBUIDORA UNIVERSAL ICA E.I.R.L | U13: 00 | V13: =VLOOKUP(U13,d_ff!A$1:B$5,2,0) -> 00: RECURSOS ORDINARIOS | W13: 2.3. 1 5. 1 2 | X13: =VLOOKUP(W13,d_clasif!B$1:C$1529,2,0) -> 2.3. 1 5. 1 2: PAPELERIA EN GENERAL, UTILES Y MATERIALES DE OFICINA | Y13: 43 | Z13: Cadenas Presupuestal: Siaf/Ord: 818/106 | AA13: 398.25 | AB13: 46164
A14: 2026 | B14: 818 | C14: 2 | D14: B | E14: 586 | F14: 106 | G14: 94.02.02 | H14: OFICINA DE ASESORIA JURIDICA | I14: 252 | J14: ATENCIÓN DE ACCIONES DE DEFENSA LEGAL DE LOS INTERESES INSTITUCIONALES EN PROCESOS JUDICIALES | K14: 71 | L14: 60 | M14: 4 | N14: 112 | O14: LAPIZ NEGRO GRADO 2B CON BORRADOR | P14: UNIDAD | Q14: 50 | R14: 0.460203 | S14: 20600944348 | T14: DISTRIBUIDORA UNIVERSAL ICA E.I.R.L | U14: 00 | V14: =VLOOKUP(U14,d_ff!A$1:B$5,2,0) -> 00: RECURSOS ORDINARIOS | W14: 2.3. 1 5. 1 2 | X14: =VLOOKUP(W14,d_clasif!B$1:C$1529,2,0) -> 2.3. 1 5. 1 2: PAPELERIA EN GENERAL, UTILES Y MATERIALES DE OFICINA | Y14: 43 | Z14: Cadenas Presupuestal: Siaf/Ord: 818/106 | AA14: 23.01 | AB14: 46164
A15: 2026 | B15: 1527 | C15: 2 | D15: B | E15: 1124 | F15: 231 | G15: 94.02.02 | H15: OFICINA DE ASESORIA JURIDICA | I15: 252 | J15: ATENCIÓN DE ACCIONES DE DEFENSA LEGAL DE LOS INTERESES INSTITUCIONALES EN PROCESOS JUDICIALES | K15: 71 | L15: 72 | M15: 5 | N15: 224 | O15: PAPEL BOND 80 G TAMAÑO A4 | P15: EMPAQUE X 500 | Q15: 28 | R15: 12.98 | S15: 20609592789 | T15: STCASMAE.I.R.L. | U15: 00 | V15: =VLOOKUP(U15,d_ff!A$1:B$5,2,0) -> 00: RECURSOS ORDINARIOS | W15: 2.3. 1 5. 1 2 | X15: =VLOOKUP(W15,d_clasif!B$1:C$1529,2,0) -> 2.3. 1 5. 1 2: PAPELERIA EN GENERAL, UTILES Y MATERIALES DE OFICINA | Y15: 43 | Z15: Cadenas Presupuestal: Siaf/Ord: 1527/231 | AA15: 363.44 | AB15: 46185
... A2511: 2026 | B2511: 165 | C2511: 2 | D2511: S | E2511: 86 | F2511: 70 | G2511: 94.02.02 | H2511: OFICINA DE ASESORIA JURIDICA | I2511: 252 | J2511: ATENCIÓN DE ACCIONES DE DEFENSA LEGAL DE LOS INTERESES INSTITUCIONALES EN PROCESOS JUDICIALES | K2511: 7 | L2511: 5 | M2511: 4 | N2511: 43 | O2511: SERVICIO ESPECIALIZADO EN MATERIA LEGAL | P2511: SERVICIO | Q2511: 10500 | R2511: 1 | S2511: 10436811123 | T2511: BOCANGEL MAMANI HANS ENDELBERTH | U2511: 00 | V2511: =VLOOKUP(U2511,d_ff!A$1:B$5,2,0) -> 00: RECURSOS ORDINARIOS | W2511: 2.3. 2 9. 1 1 | X2511: =VLOOKUP(W2511,d_clasif!B$1:C$1529,2,0) -> 2.3. 2 9. 1 1: LOCACION DE SERVICIOS REALIZADOS POR PERSONAS NATURALES RELACIONADAS AL ROL DE LA ENTIDAD | Y2511: 43 | Z2511: Cadenas Presupuestal: 94=>9001=>3999999=>5000004=>22=>6=>8=>1=>12=>27 Siaf/Ord: 165/70 | AA2511: 3465 | AB2511: 46094
A2512: 2026 | B2512: 158 | C2512: 2 | D2512: S | E2512: 89 | F2512: 58 | G2512: 94.01 | H2512: ORGANO DE CONTROL INSTITUCIONAL | I2512: 90 | J2512: REALIZACIÓN DE SERVICIOS DE CONTROL RELACIONADO | K2512: 7 | L2512: 11 | M2512: 38 | N2512: 6361 | O2512: SERVCIO ESPECIALIZADO EN CONTROL GUBERNAMENTAL | P2512: SERVICIO | Q2512: 9000 | R2512: 1 | S2512: 10700772654 | T2512: CUADROS LAGOS IZAMAR ROSALI | U2512: 00 | V2512: =VLOOKUP(U2512,d_ff!A$1:B$5,2,0) -> 00: RECURSOS ORDINARIOS | W2512: 2.3. 2 9. 1 1 | X2512: =VLOOKUP(W2512,d_clasif!B$1:C$1529,2,0) -> 2.3. 2 9. 1 1: LOCACION DE SERVICIOS REALIZADOS POR PERSONAS NATURALES RELACIONADAS AL ROL DE LA ENTIDAD | Y2512: 45 | Z2512: Cadenas Presupuestal: 94=>9001=>3999999=>5000006=>22=>6=>12=>1=>8=>27 Siaf/Ord: 158/58 | AA2512: 2970 | AB2512: 46094
A2513: 2026 | B2513: 161 | C2513: 2 | D2513: S | E2513: 132 | F2513: 107 | G2513: 94.02.19 | H2513: ESCUELA DE POSGRADO | I2513: 272 | J2513: IMPLEMENTACIÓN DEL PROCESO DE ADMISIÒN EN LA ESCUELA DE POSGRADO | K2513: 50 | L2513: 1 | M2513: 5 | N2513: 561 | O2513: SERVICIO DE IMPRESIONES EN GENERAL | P2513: SERVICIO | Q2513: 43740 | R2513: 1 | S2513: 10403020473 | T2513: MENDOZA TAPAHUASCO BERTHA | U2513: 09 | V2513: =VLOOKUP(U2513,d_ff!A$1:B$5,2,0) -> 09: RECURSOS DIRECTAMENTE RECAUDADOS | W2513: 2.3. 2 7.11 6 | X2513: =VLOOKUP(W2513,d_clasif!B$1:C$1529,2,0) -> 2.3. 2 7.11 6: SERVICIO DE IMPRESIONES, ENCUADERNACION Y EMPASTADO | Y2513: 50 | Z2513: Cadenas Presupuestal: 94=>9002=>3999999=>5000670=>22=>48=>110=>1=>589=>1 Siaf/Ord: 161/107 | AA2513: 43740 | AB2513: 46100
A2514: 2026 | B2514: 160 | C2514: 2 | D2514: S | E2514: 134 | F2514: 109 | G2514: 94.02.19 | H2514: ESCUELA DE POSGRADO | I2514: 272 | J2514: IMPLEMENTACIÓN DEL PROCESO DE ADMISIÒN EN LA ESCUELA DE POSGRADO | K2514: 70 | L2514: 10 | M2514: 2 | N2514: 185 | O2514: SERVICIO DE ELABORACION DE SPOT CON CONTENIDO AUDIOVISUAL | P2514: SERVICIO | Q2514: 10000 | R2514: 1 | S2514: 10427285656 | T2514: PIMENTEL INFANTE VICTOR HUGO | U2514: 09 | V2514: =VLOOKUP(U2514,d_ff!A$1:B$5,2,0) -> 09: RECURSOS DIRECTAMENTE RECAUDADOS | W2514: 2.3. 2 2. 4 1 | X2514: =VLOOKUP(W2514,d_clasif!B$1:C$1529,2,0) -> 2.3. 2 2. 4 1: SERVICIO DE PUBLICIDAD | Y2514: 50 | Z2514: Cadenas Presupuestal: 94=>9002=>3999999=>5000670=>22=>48=>110=>1=>589=>27 Siaf/Ord: 160/109 | AA2514: 10000 | AB2514: 46086
A2515: 2026 | B2515: 282 | C2515: 2 | D2515: S | E2515: 171 | F2515: 129 | G2515: 94.02.19 | H2515: ESCUELA DE POSGRADO | I2515: 35 | J2515: IMPLEMENTACION DEL PROCESO DE ENSEÑANZA A LOS MAESTRANDO | K2515: 7 | L2515: 11 | M2515: 38 | N2515: 2839 | O2515: SERVICIO ESPECIALIZADO EN GESTION DE LA INFORMACION | P2515: SERVICIO | Q2515: 5100 | R2515: 1 | S2515: 10746907074 | T2515: TACURI YUPANQUI LEONEL | U2515: 09 | V2515: =VLOOKUP(U2515,d_ff!A$1:B$5,2,0) -> 09: RECURSOS DIRECTAMENTE RECAUDADOS | W2515: 2.3. 2 7.14 98 | X2515: =VLOOKUP(W2515,d_clasif!B$1:C$1529,2,0) -> 2.3. 2 7.14 98: OTROS SERVICIOS TECNICOS Y PROFESIONALES DESARROLLADOS POR PERSONAS NATURALES | Y2515: 50 | Z2515: Cadenas Presupuestal: 94=>9002=>3999999=>5000670=>22=>48=>110=>1=>589=>27 Siaf/Ord: 282/129 | AA2515: 1683 | AB2515: 46111
A2516: 2026 | B2516: 283 | C2516: 2 | D2516: S | E2516: 175 | F2516: 132 | G2516: 94.02.19 | H2516: ESCUELA DE POSGRADO | I2516: 35 | J2516: IMPLEMENTACION DEL PROCESO DE ENSEÑANZA A LOS MAESTRANDO | K2516: 7 | L2516: 5 | M2516: 4 | N2516: 200 | O2516: SERVICIO ESPECIALIZADO EN COMPUTACION | P2516: SERVICIO | Q2516: 5100 | R2516: 1 | S2516: 10461009056 | T2516: CANCHARI GUTIERREZ REYZA JUDITH | U2516: 09 | V2516: =VLOOKUP(U2516,d_ff!A$1:B$5,2,0) -> 09: RECURSOS DIRECTAMENTE RECAUDADOS | W2516: 2.3. 2 7.14 98 | X2516: =VLOOKUP(W2516,d_clasif!B$1:C$1529,2,0) -> 2.3. 2 7.14 98: OTROS SERVICIOS TECNICOS Y PROFESIONALES DESARROLLADOS POR PERSONAS NATURALES | Y2516: 50 | Z2516: Cadenas Presupuestal: 94=>9002=>3999999=>5000670=>22=>48=>110=>1=>589=>27 Siaf/Ord: 283/132 | AA2516: 1683 | AB2516: 46110
A2517: 2026 | B2517: 269 | C2517: 2 | D2517: S | E2517: 168 | F2517: 128 | G2517: 94.02.19 | H2517: ESCUELA DE POSGRADO | I2517: 35 | J2517: IMPLEMENTACION DEL PROCESO DE ENSEÑANZA A LOS MAESTRANDO | K2517: 7 | L2517: 11 | M2517: 38 | N2517: 279 | O2517: SERVICIO DE DOCENCIA | P2517: SERVICIO | Q2517: 6400 | R2517: 1 | S2517: 10070991905 | T2517: PAREDES INFANZON JELIO | U2517: 09 | V2517: =VLOOKUP(U2517,d_ff!A$1:B$5,2,0) -> 09: RECURSOS DIRECTAMENTE RECAUDADOS | W2517: 2.3. 2 9. 1 1 | X2517: =VLOOKUP(W2517,d_clasif!B$1:C$1529,2,0) -> 2.3. 2 9. 1 1: LOCACION DE SERVICIOS REALIZADOS POR PERSONAS NATURALES RELACIONADAS AL ROL DE LA ENTIDAD | Y2517: 50 | Z2517: Cadenas Presupuestal: 94=>9002=>3999999=>5000670=>22=>48=>110=>1=>589=>27 Siaf/Ord: 269/128 | AA2517: 6400 | AB2517: 46090
A2518: 2026 | B2518: 287 | C2518: 2 | D2518: S | E2518: 183 | F2518: 135 | G2518: 94.02.19 | H2518: ESCUELA DE POSGRADO | I2518: 274 | J2518: REALIZACIÓN DEL FUNCIONAMIENTO DE LA ESCUELA DE POSGRADO EN LAS ACTIVIDADES ADMINISTRATIVAS | K2518: 7 | L2518: 11 | M2518: 43 | N2518: 1109 | O2518: SERVICIO DE SEGUIMIENTO DE DOCUMENTOS ADMINISTRATIVOS | P2518: SERVICIO | Q2518: 3400 | R2518: 1 | S2518: 10762496122 | T2518: QUISPE BENDEZU MARCO ANTONIO | U2518: 09 | V2518: =VLOOKUP(U2518,d_ff!A$1:B$5,2,0) -> 09: RECURSOS DIRECTAMENTE RECAUDADOS | W2518: 2.3. 2 9. 1 1 | X2518: =VLOOKUP(W2518,d_clasif!B$1:C$1529,2,0) -> 2.3. 2 9. 1 1: LOCACION DE SERVICIOS REALIZADOS POR PERSONAS NATURALES RELACIONADAS AL ROL DE LA ENTIDAD | Y2518: 50 | Z2518: Cadenas Presupuestal: 94=>9002=>3999999=>5000670=>22=>48=>110=>1=>589=>27 Siaf/Ord: 287/135 | AA2518: 1700 | AB2518: 46111
A2519: 2026 | B2519: 323 | C2519: 2 | D2519: S | E2519: 180 | F2519: 133 | G2519: 94.02.19 | H2519: ESCUELA DE POSGRADO | I2519: 35 | J2519: IMPLEMENTACION DEL PROCESO DE ENSEÑANZA A LOS MAESTRANDO | K2519: 7 | L2519: 11 | M2519: 38 | N2519: 279 | O2519: SERVICIO DE DOCENCIA | P2519: SERVICIO | Q2519: 5760 | R2519: 1 | S2519: 10282898522 | T2519: QUISPE QUISPE JOSE ANTONIO | U2519: 09 | V2519: =VLOOKUP(U2519,d_ff!A$1:B$5,2,0) -> 09: RECURSOS DIRECTAMENTE RECAUDADOS | W2519: 2.3. 2 9. 1 1 | X2519: =VLOOKUP(W2519,d_clasif!B$1:C$1529,2,0) -> 2.3. 2 9. 1 1: LOCACION DE SERVICIOS REALIZADOS POR PERSONAS NATURALES RELACIONADAS AL ROL DE LA ENTIDAD | Y2519: 50 | Z2519: Cadenas Presupuestal: 94=>9002=>3999999=>5000670=>22=>48=>110=>1=>589=>27 Siaf/Ord: 323/133 | AA2519: 5760 | AB2519: 46099
A2520: 2026 | B2520: 559 | C2520: 2 | D2520: S | E2520: 398 | F2520: 277 | G2520: 94.02.19 | H2520: ESCUELA DE POSGRADO | I2520: 35 | J2520: IMPLEMENTACION DEL PROCESO DE ENSEÑANZA A LOS MAESTRANDO | K2520: 7 | L2520: 11 | M2520: 38 | N2520: 279 | O2520: SERVICIO DE DOCENCIA | P2520: SERVICIO | Q2520: 5760 | R2520: 1 | S2520: 10074767031 | T2520: PIMENTEL LLAMOCCA ENRIQUE LUIS | U2520: 09 | V2520: =VLOOKUP(U2520,d_ff!A$1:B$5,2,0) -> 09: RECURSOS DIRECTAMENTE RECAUDADOS | W2520: 2.3. 2 9. 1 1 | X2520: =VLOOKUP(W2520,d_clasif!B$1:C$1529,2,0) -> 2.3. 2 9. 1 1: LOCACION DE SERVICIOS REALIZADOS POR PERSONAS NATURALES RELACIONADAS AL ROL DE LA ENTIDAD | Y2520: 50 | Z2520: Cadenas Presupuestal: 94=>9002=>3999999=>5000670=>22=>48=>110=>1=>589=>27 Siaf/Ord: 559/277 | AA2520: 5760 | AB2520: 46105
A2521: 2026 | B2521: 503 | C2521: 2 | D2521: S | E2521: 362 | F2521: 254 | G2521: 94.02.08.07 | H2521: UNIDAD EJECUTORA DE INVERSIONES | I2521: 381 | J2521: MEJORAM Y AMPLIAC DEL SERV DE GESTION INSTIT EN EL SISTEMA DE VIDEO VIGILANCIA Y CONTROL DE ACCESO DE PERSONAS EN LA CIUDAD UNIVERSITARIA DE LA UNSCH | K2521: 7 | L2521: 5 | M2521: 3 | N2521: 622 | O2521: SERVICIO DE EXAMEN MEDICO OCUPACIONAL | P2521: SERVICIO | Q2521: 2704 | R2521: 1 | S2521: 20608052080 | T2521: EPSS ESPECIALIDADES MEDICAS ONCOLABS E.I.R.L. | U2521: 00 | V2521: =VLOOKUP(U2521,d_ff!A$1:B$5,2,0) -> 00: RECURSOS ORDINARIOS | W2521: 2.6. 2 2. 2 5 | X2521: =VLOOKUP(W2521,d_clasif!B$1:C$1529,2,0) -> 2.6. 2 2. 2 5: COSTO DE CONSTRUCCION POR ADMINISTRACION DIRECTA - SERVICIOS | Y2521: 63 | Z2521: Cadenas Presupuestal: 94=>66=>2534035=>4000040=>22=>48=>10=>1=>37703=>1 Siaf/Ord: 503/254 | AA2521: 2704 | AB2521: 46125
A2522: 2026 | B2522: 582 | C2522: 2 | D2522: S | E2522: 438 | F2522: 293 | G2522: 94.02.08.07 | H2522: UNIDAD EJECUTORA DE INVERSIONES | I2522: 381 | J2522: MEJORAM Y AMPLIAC DEL SERV DE GESTION INSTIT EN EL SISTEMA DE VIDEO VIGILANCIA Y CONTROL DE ACCESO DE PERSONAS EN LA CIUDAD UNIVERSITARIA DE LA UNSCH | K2522: 85 | L2522: 1 | M2522: 7 | N2522: 6 | O2522: SEGURO COMPLEMENTARIO DE TRABAJO DE RIESGO - PENSION | P2522: SERVICIO | Q2522: 639 | R2522: 1 | S2522: 20418896915 | T2522: MAPFRE PERU COMPAÑIA DE SEGUROS Y REASEGUROS | U2522: 00 | V2522: =VLOOKUP(U2522,d_ff!A$1:B$5,2,0) -> 00: RECURSOS ORDINARIOS | W2522: 2.6. 2 2. 2 5 | X2522: =VLOOKUP(W2522,d_clasif!B$1:C$1529,2,0) -> 2.6. 2 2. 2 5: COSTO DE CONSTRUCCION POR ADMINISTRACION DIRECTA - SERVICIOS | Y2522: 63 | Z2522: Cadenas Presupuestal: 94=>66=>2534035=>4000040=>22=>48=>10=>1=>37703=>1 Siaf/Ord: 582/293 | AA2522: 639.49 | AB2522: 46140
A2523: 2026 | B2523: 584 | C2523: 2 | D2523: S | E2523: 439 | F2523: 296 | G2523: 94.02.08.07 | H2523: UNIDAD EJECUTORA DE INVERSIONES | I2523: 381 | J2523: MEJORAM Y AMPLIAC DEL SERV DE GESTION INSTIT EN EL SISTEMA DE VIDEO VIGILANCIA Y CONTROL DE ACCESO DE PERSONAS EN LA CIUDAD UNIVERSITARIA DE LA UNSCH | K2523: 85 | L2523: 1 | M2523: 7 | N2523: 7 | O2523: SEGURO COMPLEMENTARIO DE TRABAJO DE RIESGO - SALUD | P2523: SERVICIO | Q2523: 704 | R2523: 1 | S2523: 20517182673 | T2523: MAPFRE PERU S.A. ENTIDAD PRESTADORA DE SALUD | U2523: 00 | V2523: =VLOOKUP(U2523,d_ff!A$1:B$5,2,0) -> 00: RECURSOS ORDINARIOS | W2523: 2.6. 2 2. 2 5 | X2523: =VLOOKUP(W2523,d_clasif!B$1:C$1529,2,0) -> 2.6. 2 2. 2 5: COSTO DE CONSTRUCCION POR ADMINISTRACION DIRECTA - SERVICIOS | Y2523: 63 | Z2523: Cadenas Presupuestal: 94=>66=>2534035=>4000040=>22=>48=>10=>1=>37703=>1 Siaf/Ord: 584/296 | AA2523: 703.65 | AB2523: 46140
A2524: 2026 | B2524: 373 | C2524: 2 | D2524: S | E2524: 274 | F2524: 198 | G2524: 94.02.08.07 | H2524: UNIDAD EJECUTORA DE INVERSIONES | I2524: 381 | J2524: MEJORAM Y AMPLIAC DEL SERV DE GESTION INSTIT EN EL SISTEMA DE VIDEO VIGILANCIA Y CONTROL DE ACCESO DE PERSONAS EN LA CIUDAD UNIVERSITARIA DE LA UNSCH | K2524: 94 | L2524: 20 | M2524: 3 | N2524: 10 | O2524: ALQUILER DE CAMIONETA | P2524: SERVICIO | Q2524: 2324 | R2524: 1 | S2524: 10485476402 | T2524: FLORES RIVEROS FLOR MARIA | U2524: 00 | V2524: =VLOOKUP(U2524,d_ff!A$1:B$5,2,0) -> 00: RECURSOS ORDINARIOS | W2524: 2.6. 2 2. 2 5 | X2524: =VLOOKUP(W2524,d_clasif!B$1:C$1529,2,0) -> 2.6. 2 2. 2 5: COSTO DE CONSTRUCCION POR ADMINISTRACION DIRECTA - SERVICIOS | Y2524: 63 | Z2524: Cadenas Presupuestal: 94=>66=>2534035=>4000040=>22=>48=>10=>1=>37703=>2 Siaf/Ord: 373/198 | AA2524: 2324 | AB2524: 46118
... A2698: 2026 | B2698: 165 | C2698: 2 | D2698: S | E2698: 86 | F2698: 70 | G2698: 94.02.02 | H2698: OFICINA DE ASESORIA JURIDICA | I2698: 252 | J2698: ATENCIÓN DE ACCIONES DE DEFENSA LEGAL DE LOS INTERESES INSTITUCIONALES EN PROCESOS JUDICIALES | K2698: 7 | L2698: 5 | M2698: 4 | N2698: 43 | O2698: SERVICIO ESPECIALIZADO EN MATERIA LEGAL | P2698: SERVICIO | Q2698: 10500 | R2698: 1 | S2698: 10436811123 | T2698: BOCANGEL MAMANI HANS ENDELBERTH | U2698: 00 | V2698: =VLOOKUP(U2698,d_ff!A$1:B$5,2,0) -> 00: RECURSOS ORDINARIOS | W2698: 2.3. 2 9. 1 1 | X2698: =VLOOKUP(W2698,d_clasif!B$1:C$1529,2,0) -> 2.3. 2 9. 1 1: LOCACION DE SERVICIOS REALIZADOS POR PERSONAS NATURALES RELACIONADAS AL ROL DE LA ENTIDAD | Y2698: 43 | Z2698: Cadenas Presupuestal: 94=>9001=>3999999=>5000004=>22=>6=>8=>1=>12=>27 Siaf/Ord: 165/70 | AA2698: 3465 | AB2698: 46125
A2699: 2026 | B2699: 158 | C2699: 2 | D2699: S | E2699: 89 | F2699: 58 | G2699: 94.01 | H2699: ORGANO DE CONTROL INSTITUCIONAL | I2699: 90 | J2699: REALIZACIÓN DE SERVICIOS DE CONTROL RELACIONADO | K2699: 7 | L2699: 11 | M2699: 38 | N2699: 6361 | O2699: SERVCIO ESPECIALIZADO EN CONTROL GUBERNAMENTAL | P2699: SERVICIO | Q2699: 9000 | R2699: 1 | S2699: 10700772654 | T2699: CUADROS LAGOS IZAMAR ROSALI | U2699: 00 | V2699: =VLOOKUP(U2699,d_ff!A$1:B$5,2,0) -> 00: RECURSOS ORDINARIOS | W2699: 2.3. 2 9. 1 1 | X2699: =VLOOKUP(W2699,d_clasif!B$1:C$1529,2,0) -> 2.3. 2 9. 1 1: LOCACION DE SERVICIOS REALIZADOS POR PERSONAS NATURALES RELACIONADAS AL ROL DE LA ENTIDAD | Y2699: 45 | Z2699: Cadenas Presupuestal: 94=>9001=>3999999=>5000006=>22=>6=>12=>1=>8=>27 Siaf/Ord: 158/58 | AA2699: 2970 | AB2699: 46134
A2700: 2026 | B2700: 333 | C2700: 2 | D2700: S | E2700: 218 | F2700: 172 | G2700: 94.04.04 | H2700: INSTITUTO DE INVESTIGACION | I2700: 378 | J2700: IMPLEMENTACION PARA EL DESARROLLO Y EJECUCION DE LAS ACTIVIDADES PARA LA INVESTIGACION | K2700: 7 | L2700: 11 | M2700: 43 | N2700: 1207 | O2700: SERVICIO DE AUXILIAR ADMINISTRATIVO | P2700: SERVICIO | Q2700: 6000 | R2700: 1 | S2700: 10712403158 | T2700: CONGA CARDENAS JHONY | U2700: 18 | V2700: =VLOOKUP(U2700,d_ff!A$1:B$5,2,0) -> 18: CANON Y SOBRECANON, REGALIAS, RENTA DE ADUANAS Y PARTICIPACIONES | W2700: 2.3. 2 9. 1 1 | X2700: =VLOOKUP(W2700,d_clasif!B$1:C$1529,2,0) -> 2.3. 2 9. 1 1: LOCACION DE SERVICIOS REALIZADOS POR PERSONAS NATURALES RELACIONADAS AL ROL DE LA ENTIDAD | Y2700: 53 | Z2700: Cadenas Presupuestal: 94=>9002=>3999999=>5000894=>22=>48=>15=>1=>334523=>27 Siaf/Ord: 333/172 | AA2700: 1980 | AB2700: 46121
A2701: 2026 | B2701: 334 | C2701: 2 | D2701: S | E2701: 223 | F2701: 173 | G2701: 94.04.04 | H2701: INSTITUTO DE INVESTIGACION | I2701: 378 | J2701: IMPLEMENTACION PARA EL DESARROLLO Y EJECUCION DE LAS ACTIVIDADES PARA LA INVESTIGACION | K2701: 17 | L2701: 1 | M2701: 3 | N2701: 1226 | O2701: SERVICIO DE IMPLEMENTACIÓN DE PLATAFORMA TECNOLÓGICA | P2701: SERVICIO | Q2701: 6000 | R2701: 1 | S2701: 10772239934 | T2701: GUTIERREZ ROJAS ALEXANDRO ANTHONY | U2701: 18 | V2701: =VLOOKUP(U2701,d_ff!A$1:B$5,2,0) -> 18: CANON Y SOBRECANON, REGALIAS, RENTA DE ADUANAS Y PARTICIPACIONES | W2701: 2.3. 2 9. 1 1 | X2701: =VLOOKUP(W2701,d_clasif!B$1:C$1529,2,0) -> 2.3. 2 9. 1 1: LOCACION DE SERVICIOS REALIZADOS POR PERSONAS NATURALES RELACIONADAS AL ROL DE LA ENTIDAD | Y2701: 53 | Z2701: Cadenas Presupuestal: 94=>9002=>3999999=>5000894=>22=>48=>15=>1=>334523=>27 Siaf/Ord: 334/173 | AA2701: 1980 | AB2701: 46120
A2702: 2026 | B2702: 335 | C2702: 2 | D2702: S | E2702: 217 | F2702: 171 | G2702: 94.04.04 | H2702: INSTITUTO DE INVESTIGACION | I2702: 378 | J2702: IMPLEMENTACION PARA EL DESARROLLO Y EJECUCION DE LAS ACTIVIDADES PARA LA INVESTIGACION | K2702: 7 | L2702: 11 | M2702: 44 | N2702: 3759 | O2702: SERVICIO ESPECIALIZADO EN ASISTENCIA TECNICA ADMINISTRATIVA | P2702: SERVICIO | Q2702: 9000 | R2702: 1 | S2702: 10410548807 | T2702: HERRERA TAYPE IRMA MAGALY | U2702: 18 | V2702: =VLOOKUP(U2702,d_ff!A$1:B$5,2,0) -> 18: CANON Y SOBRECANON, REGALIAS, RENTA DE ADUANAS Y PARTICIPACIONES | W2702: 2.3. 2 9. 1 1 | X2702: =VLOOKUP(W2702,d_clasif!B$1:C$1529,2,0) -> 2.3. 2 9. 1 1: LOCACION DE SERVICIOS REALIZADOS POR PERSONAS NATURALES RELACIONADAS AL ROL DE LA ENTIDAD | Y2702: 53 | Z2702: Cadenas Presupuestal: 94=>9002=>3999999=>5000894=>22=>48=>15=>1=>334523=>27 Siaf/Ord: 335/171 | AA2702: 2970 | AB2702: 46120
A2703: 2026 | B2703: 336 | C2703: 2 | D2703: S | E2703: 221 | F2703: 170 | G2703: 94.04.04 | H2703: INSTITUTO DE INVESTIGACION | I2703: 378 | J2703: IMPLEMENTACION PARA EL DESARROLLO Y EJECUCION DE LAS ACTIVIDADES PARA LA INVESTIGACION | K2703: 7 | L2703: 11 | M2703: 44 | N2703: 3759 | O2703: SERVICIO ESPECIALIZADO EN ASISTENCIA TECNICA ADMINISTRATIVA | P2703: SERVICIO | Q2703: 9000 | R2703: 1 | S2703: 10459745284 | T2703: VEGA ROJAS NADIA JOSEFINA | U2703: 18 | V2703: =VLOOKUP(U2703,d_ff!A$1:B$5,2,0) -> 18: CANON Y SOBRECANON, REGALIAS, RENTA DE ADUANAS Y PARTICIPACIONES | W2703: 2.3. 2 9. 1 1 | X2703: =VLOOKUP(W2703,d_clasif!B$1:C$1529,2,0) -> 2.3. 2 9. 1 1: LOCACION DE SERVICIOS REALIZADOS POR PERSONAS NATURALES RELACIONADAS AL ROL DE LA ENTIDAD | Y2703: 53 | Z2703: Cadenas Presupuestal: 94=>9002=>3999999=>5000894=>22=>48=>15=>1=>334523=>27 Siaf/Ord: 336/170 | AA2703: 2970 | AB2703: 46120
A2704: 2026 | B2704: 379 | C2704: 2 | D2704: S | E2704: 220 | F2704: 193 | G2704: 94.04.04 | H2704: INSTITUTO DE INVESTIGACION | I2704: 378 | J2704: IMPLEMENTACION PARA EL DESARROLLO Y EJECUCION DE LAS ACTIVIDADES PARA LA INVESTIGACION | K2704: 70 | L2704: 10 | M2704: 2 | N2704: 151 | O2704: SERVICIO DE DIGITALIZACIÓN DE DOCUMENTOS | P2704: SERVICIO | Q2704: 6000 | R2704: 1 | S2704: 10726069277 | T2704: MENESES NOLASCO THORMAN | U2704: 18 | V2704: =VLOOKUP(U2704,d_ff!A$1:B$5,2,0) -> 18: CANON Y SOBRECANON, REGALIAS, RENTA DE ADUANAS Y PARTICIPACIONES | W2704: 2.3. 2 9. 1 1 | X2704: =VLOOKUP(W2704,d_clasif!B$1:C$1529,2,0) -> 2.3. 2 9. 1 1: LOCACION DE SERVICIOS REALIZADOS POR PERSONAS NATURALES RELACIONADAS AL ROL DE LA ENTIDAD | Y2704: 53 | Z2704: Cadenas Presupuestal: 94=>9002=>3999999=>5000894=>22=>48=>15=>1=>334523=>27 Siaf/Ord: 379/193 | AA2704: 1980 | AB2704: 46132
A2705: 2026 | B2705: 139 | C2705: 2 | D2705: S | E2705: 64 | F2705: 47 | G2705: 94.02.13.06 | H2705: PLANTELES DE APLICACION GUAMAN POMA DE AYALA | I2705: 26 | J2705: IMPLEMENTACIÓN Y DESARROLLO DE LA EDUCACIÓN EN COLEGIOS EXPERIMENTALES | K2705: 87 | L2705: 5 | M2705: 3 | N2705: 19 | O2705: SERVICIO DE INTERNET | P2705: SERVICIO | Q2705: 1200 | R2705: 1 | S2705: 20452245460 | T2705: SOCIEDAD INTEGRADA DE ELECTRONICA Y SISTEMAS SRL | U2705: 00 | V2705: =VLOOKUP(U2705,d_ff!A$1:B$5,2,0) -> 00: RECURSOS ORDINARIOS | W2705: 2.3. 2 2. 2 3 | X2705: =VLOOKUP(W2705,d_clasif!B$1:C$1529,2,0) -> 2.3. 2 2. 2 3: SERVICIO DE INTERNET | Y2705: 47 | Z2705: Cadenas Presupuestal: 94=>9002=>3999999=>5000659=>22=>48=>109=>1=>44444=>1 Siaf/Ord: 139/47 | AA2705: 218.18 | AB2705: 46127
A2706: 2026 | B2706: 417 | C2706: 2 | D2706: S | E2706: 297 | F2706: 220 | G2706: 94.02.13.06 | H2706: PLANTELES DE APLICACION GUAMAN POMA DE AYALA | I2706: 26 | J2706: IMPLEMENTACIÓN Y DESARROLLO DE LA EDUCACIÓN EN COLEGIOS EXPERIMENTALES | K2706: 7 | L2706: 11 | M2706: 44 | N2706: 608 | O2706: SERVICIO DE ASISTENCIA TECNICA Y ORIENTACION EN AUXILIAR EN EDUCACION | P2706: SERVICIO | Q2706: 10000 | R2706: 1 | S2706: 10283163810 | T2706: OCHANTE APAICO ROSA | U2706: 00 | V2706: =VLOOKUP(U2706,d_ff!A$1:B$5,2,0) -> 00: RECURSOS ORDINARIOS | W2706: 2.3. 2 9. 1 1 | X2706: =VLOOKUP(W2706,d_clasif!B$1:C$1529,2,0) -> 2.3. 2 9. 1 1: LOCACION DE SERVICIOS REALIZADOS POR PERSONAS NATURALES RELACIONADAS AL ROL DE LA ENTIDAD | Y2706: 47 | Z2706: Cadenas Presupuestal: 94=>9002=>3999999=>5000659=>22=>48=>109=>1=>44444=>27 Siaf/Ord: 417/220 | AA2706: 2000 | AB2706: 46139
A2707: 2026 | B2707: 418 | C2707: 2 | D2707: S | E2707: 298 | F2707: 221 | G2707: 94.02.13.06 | H2707: PLANTELES DE APLICACION GUAMAN POMA DE AYALA | I2707: 26 | J2707: IMPLEMENTACIÓN Y DESARROLLO DE LA EDUCACIÓN EN COLEGIOS EXPERIMENTALES | K2707: 7 | L2707: 5 | M2707: 4 | N2707: 16 | O2707: SERVICIO ESPECIALIZADO EN PSICOLOGIA | P2707: SERVICIO | Q2707: 10000 | R2707: 1 | S2707: 10739071955 | T2707: GUTIERREZ GAMBOA KELLY ALISSON | U2707: 00 | V2707: =VLOOKUP(U2707,d_ff!A$1:B$5,2,0) -> 00: RECURSOS ORDINARIOS | W2707: 2.3. 2 9. 1 1 | X2707: =VLOOKUP(W2707,d_clasif!B$1:C$1529,2,0) -> 2.3. 2 9. 1 1: LOCACION DE SERVICIOS REALIZADOS POR PERSONAS NATURALES RELACIONADAS AL ROL DE LA ENTIDAD | Y2707: 47 | Z2707: Cadenas Presupuestal: 94=>9002=>3999999=>5000659=>22=>48=>109=>1=>44444=>27 Siaf/Ord: 418/221 | AA2707: 2000 | AB2707: 46137
A2708: 2026 | B2708: 421 | C2708: 2 | D2708: S | E2708: 301 | F2708: 215 | G2708: 94.02.13.06 | H2708: PLANTELES DE APLICACION GUAMAN POMA DE AYALA | I2708: 26 | J2708: IMPLEMENTACIÓN Y DESARROLLO DE LA EDUCACIÓN EN COLEGIOS EXPERIMENTALES | K2708: 7 | L2708: 11 | M2708: 38 | N2708: 898 | O2708: SERVICIOS ESPECIALIZADOS EN EDUCACION PRIMARIA | P2708: SERVICIO | Q2708: 12500 | R2708: 1 | S2708: 10704335682 | T2708: QUISPE PALOMINO TALIA NATALY | U2708: 00 | V2708: =VLOOKUP(U2708,d_ff!A$1:B$5,2,0) -> 00: RECURSOS ORDINARIOS | W2708: 2.3. 2 9. 1 1 | X2708: =VLOOKUP(W2708,d_clasif!B$1:C$1529,2,0) -> 2.3. 2 9. 1 1: LOCACION DE SERVICIOS REALIZADOS POR PERSONAS NATURALES RELACIONADAS AL ROL DE LA ENTIDAD | Y2708: 47 | Z2708: Cadenas Presupuestal: 94=>9002=>3999999=>5000659=>22=>48=>109=>1=>44444=>27 Siaf/Ord: 421/215 | AA2708: 2500 | AB2708: 46139
...

Sheet d_ff
A1: fuente_financ | B1: nombre_ff
A2: 00 | B2: 00: RECURSOS ORDINARIOS
A3: 09 | B3: 09: RECURSOS DIRECTAMENTE RECAUDADOS
A4: 18 | B4: 18: CANON Y SOBRECANON, REGALIAS, RENTA DE ADUANAS Y PARTICIPACIONES
A5: 13 | B5: 13: DONACIONES Y TRANSFERENCIAS

Sheet d_clasif
A1: CLASIFICADOR | B1: CLASIFICADOR | C1: NOMBRE_CLASIF
A2: 1.1.1.1.1.1 | B2: 1.1. 1 1. 1 1 | C2: 1.1. 1 1. 1 1: RENTA DE TERCERA CATEGORIA
A3: 1.1.1.1.2.1 | B3: 1.1. 1 1. 2 1 | C3: 1.1. 1 1. 2 1: RENTA DE PRIMERA CATEGORIA
A4: 1.1.1.1.2.2 | B4: 1.1. 1 1. 2 2 | C4: 1.1. 1 1. 2 2: RENTA DE SEGUNDA CATEGORIA
A5: 1.1.1.1.2.3 | B5: 1.1. 1 1. 2 3 | C5: 1.1. 1 1. 2 3: RENTA DE CUARTA CATEGORIA
A6: 1.1.1.1.2.4 | B6: 1.1. 1 1. 2 4 | C6: 1.1. 1 1. 2 4: RENTA DE QUINTA CATEGORIA
A7: 1.1.1.2.1.1 | B7: 1.1. 1 2. 1 1 | C7: 1.1. 1 2. 1 1: IMPUESTO A LA RENTA DE NO DOMICILIADOS
A8: 1.1.1.3.1.1 | B8: 1.1. 1 3. 1 1 | C8: 1.1. 1 3. 1 1: REGIMEN ESPECIAL DE IMPUESTO A LA RENTA
A9: 1.1.1.4.1.1 | B9: 1.1. 1 4. 1 1 | C9: 1.1. 1 4. 1 1: REGIMEN PARA LA AMAZONIA
A10: 1.1.1.4.1.2 | B10: 1.1. 1 4. 1 2 | C10: 1.1. 1 4. 1 2: REGIMEN AGRARIO
A11: 1.1.1.4.1.3 | B11: 1.1. 1 4. 1 3 | C11: 1.1. 1 4. 1 3: REGIMEN DE FRONTERA
A12: 1.1.1.5.1.1 | B12: 1.1. 1 5. 1 1 | C12: 1.1. 1 5. 1 1: REGULARIZACION DE IMPUESTO A LA RENTA DE PERSONAS JURIDICAS
... A1529: 2.2.2.1.3.1 | B1529: 2.2. 2 1. 3 1 | C1529: 2.2. 2 1. 3 1: GASTOS DE SEPELIO Y LUTO DEL PERSONAL ACTIVO
